Workbook

Sheet WELCOME
B1: Untuk menghindari ERROR jangan mengubah, menambah atau mengurangi kolom, isi berurutan dari sheet CONTENT PILLAR MAPPING - SCRIPT PROMPT GENERATOR - HOOK GENERATOR - CAPTION GENERATOR - CONTENT BATCHING
B3: Video Tutorial Penggunaan
B10: Kenalan dulu yuk! | E10: Tulis nama kamu di sini 🙌🏻
B12: Template ini dirancang sebagai alat fleksibel yang dapat kamu gunakan untuk: | P12: Dengan template ini, kamu akan memiliki sistem terpadu untuk:
B13: 1 | C13: Personal Branding/Pribadi: Mengembangkan konten untuk diri sendiri dan membangun otoritas personal. | P13: 1 | Q13: Concepting: Menentukan DNA konten dan pilar strategis.
B14: 2 | C14: UMKM: Membuat strategi konten yang efektif untuk bisnis skala kecil/menengah. | P14: 2 | Q14: Scripting: Menghasilkan ide dan draf skrip siap pakai.
B15: 3 | C15: Klien/Brand: Membantu klien atau brand Anda dalam memproduksi konten yang relevan dan strategis. | P15: 3 | Q15: Shooting & Editing: Mengelola aset produksi dan melacak progres.
P16: 4 | Q16: Posting & Scheduling: Merencanakan dan menjadwalkan konten dengan mudah.
B17: ⚠️ Penting ⚠️ | C17: Saat mengisi, pastikan untuk menyesuaikan Niche, Positioning, Tone of Voice, Target Audiens, dan elemen lainnya sesuai dengan niche atau bidang spesifik dari akun (pribadi/klien/UMKM/brand) yang sedang Anda kerjakan. | P17: 5 | Q17: Evaluating: Menganalisis kinerja untuk optimasi berkelanjutan.
B19: Prasyarat Penting: | P19: Alur Penggunaan Template:
B20: Untuk hasil optimal, pastikan kamu memiliki: | P20: 1 | Q20: Definisikan Fondasi Konten: Isi detail di 'CONTENT PILLAR MAPPING'.
B21: Chrome atau Safari dan ChatGPT atau Gemini | P21: 2 | Q21: Hasilkan Content Pillar: Gunakan prompt di 'CONTENT PILLAR MAPPING'.
P22: 3 | Q22: Buat Ide & Skrip Konten: Gunakan 'SCRIPT PROMPT GENERATOR'.
P23: 4 | Q23: Atur Produksi & Jadwal: Gunakan 'BATCHING KONTEN'.
P24: 5 | Q24: Tinjau Hasil Akhir: Lihat skrip di 'HASIL KONTEN'."
B26: Langkah Awal Krusial: Memahami Niche & Content Pillar | P26: Penjelasan Singkat Setiap Sheet:
B27: Template ini bekerja paling efektif jika kamu memahami niche dan positioningmu. Informasi ini adalah fondasi semua prompt AI. | P27: 1 | Q27: CONTENT PILLAR MAPPING: Menentukan DNA konten & pilar strategis.
B28: Apa itu Niche & Content Pillar? | P28: 2 | Q28: SCRIPT PROMPT GENERATOR: Menghasilkan ide & skrip konten.
B29: 1 | C29: Niche: Bidang luas yang kamu geluti | P29: 3 | Q29: BATCHING KONTEN: Mengelola produksi & jadwal konten.
B30: 2 | C30: Content Pillar: Topik utama yang mendukung nichemu.
B32: Berikan Feedback & Testimoni: Dapatkan FREE ACCESS EBOOK CONTENT PILLAR | P32: Berikan Feedback & Testimoni: Dapatkan FREE Template Kalender 1 Tahun dengan mengisi feedback & testimoni
B33: 🙌🏻 LINK FEEDBACK & TESTIMONI 🙌🏻
B38: Masih Bingung? Hubungi Saya! | P38: Hak Cipta & Afiliasi:
B39: Jika ada pertanyaan, jangan ragu DM saya di IG: @fajarmuliawn
B43: Ingin menjual kembali template ini? Dapatkan link affiliate kamu di sini 👉🏻 | P43: 🙌🏻 LINK AFFILIATE 🙌🏻
P45: https://lynk.id/fajarmuliawn/jg7p6nwdkvdx

Sheet CONTENT PILLAR MAPPING
B1: Isi Niche Kamu di Kolom Berikut 👉🏻 | C1: Niche | E1: Spesifik Niche | F1: Super Spesifik Niche | G1: Apa itu Brand Archetype?
C2: Platform Informasi Peluang & Leadership | E2: Platform info peluang, pengembangan diri, dan karier untuk pelajar & mahasiswa Indonesia | F2: Platform kurasi peluang, insight, dan strategi growth untuk anak muda yang mau naik level | G2: Brand archetype adalah karakter atau kepribadian dasar yang digunakan brand (termasuk personal branding) untuk membentuk citra, cara berkomunikasi, dan membangun koneksi emosional dengan audiens.
B4: Isi Kepribadian/Positioning Kamu di Kolom Berikut 👉🏻 | C4: Positioning (Kamu Ingin Dikenal Sebagai Siapa) | G4: Sederhananya: Brand archetype itu seperti “karakter khas” yang mewakili cara brand berbicara, bersikap, dan ingin dikenali oleh audiensnya.
C5: Sumber peluang, insight, dan guidance paling relevan untuk anak muda ambis
B9: Kita Cari Tahu DNA Content Pillar-mu, Isi semuanya jangan ada yang terlewat 👉🏻 | C9: Tone of Voice | D9: Brand Archetype | E9: Deskripsi Gaya Komunikasi | F9: Contoh Pengisian | G9: Brand Archetype
C10: Friendly | D10: The Magician | E10: Informatif, suportif, dan to the point. Kontennya harus bikin audiens ngerasa peluang, growth, dan karier itu bisa diubah jadi aksi nyata langkah demi langkah. | F10: Saya suka menyampaikan pesan dengan cara santai dan dekat dengan audiens. | G10: The Creator Ingin menciptakan sesuatu yang orisinal dan bermakna. Fokus pada kreativitas dan karya.
F11: Saya terbiasa menyampaikan hal serius dengan gaya profesional tapi tetap ringan. | G11: The Ruler Tampil sebagai pemimpin. Profesional, tegas, dan dipercaya. Cocok untuk brand yang ingin terlihat kuat dan mapan.
F12: Saya suka storytelling, jadi suka membawa audiens lewat pengalaman pribadi. | G12: The Hero Penuh semangat, suka tantangan, dan mendorong audiens jadi versi terbaik dirinya.
F13: Saya lebih suka gaya to the point dan actionable, langsung ke solusi. | G13: The Caregiver Peduli, melayani, dan membantu. Cocok untuk brand yang menenangkan dan memberi rasa aman.
F14: Gaya saya menghibur, tapi tetap ada nilai edukasinya. | G14: The Explorer Suka petualangan dan kebebasan. Membawa audiens untuk bertumbuh dan menjelajah hal baru.
F15: Saya biasanya menggunakan gaya visual yang kuat saat menyampaikan konten. | G15: The Innocent Simple, jujur, dan positif. Bawa rasa damai dan optimisme dalam setiap pesannya.
F16: Gaya saya lebih ke membangun empati dan koneksi emosional. | G16: The Rebel Anti-mainstream, berani beda, dan ingin mematahkan aturan lama.
G17: The Lover Fokus pada hubungan emosional dan keindahan. Dekat, hangat, dan penuh rasa.
C18: Target Audience | D18: Pelajar SMA, mahasiswa, dan fresh graduate usia 15-25 tahun di Indonesia yang aktif cari peluang pengembangan diri, karier, prestasi, dan networking. | F18: Tentukan siapa yang ingin kamu jangkau dengan kontenmu. Sebutkan secara spesifik: usia, minat, profesi, atau tantangan yang mereka hadapi. Contoh: ‘UMKM pemula yang ingin mulai jualan online’, atau ‘fresh graduate yang ingin jadi konten kreator | G18: The Magician Membawa perubahan dan “wow moment”. Cocok untuk brand yang transformative atau inovatif.
C19: Segmentasi Audience | D19: Opportunity seeker, scholarship hunter, future leader, CV builder, dan anak muda yang ingin naik level lewat pengalaman dan skill. | G19: The Everyman Ramah, relatable, dan down to earth. Seperti teman dekat yang bisa diandalkan.
C20: =IF(AND(C2<>"", E2<>"", F2<>"", C5<>"", C10<>"", D10<>"", E10<>"", D18<>"", D19<>""), CONCATENATE("Saya adalah seorang dengan niche utama '", C2, "', spesifik kategori '", E2, "', dan super spesifik '", F2, "', yang ingin dikenal sebagai '", C5, "'.", CHAR(10), CHAR(10), "Saya memiliki Tone of Voice: '", C10, "', Brand Archetype: '", D10, "', dan Deskripsi Gaya Komunikasi: '", E10, "'.", CHAR(10), CHAR(10), "Target audiens saya adalah: '", D18, "', dengan segmentasi audiens: '", D19, "'.", CHAR(10), CHAR(10), "Berdasarkan informasi di atas dan dengan menerapkan framework STP (Segmenting, Targeting, Positioning), mohon buatkan daftar Content Pilar yang lengkap, relevan, dan strategis untuk akun media sosial saya. Ini adalah DNA konten saya. **Pastikan setiap pilar ini unik dan membedakan saya dari kreator lain di niche yang sama, serta selaras dengan tujuan personal branding saya.**", CHAR(10), CHAR(10), "Daftar content pilar ini harus mencakup:", CHAR(10), "> Topik utama yang relevan dengan niche dan bisa dikembangkan dalam jangka panjang.", CHAR(10), "> Sub-topik turunan yang **spesifik, relevan, dan dapat langsung menjadi ide konten yang menarik serta menjawab pain points audiens.**", CHAR(10), "> Mencakup 5 pilar konten utama yang meliputi: Educational (Edukasi), Entertain (Hiburan), Social Proof (Bukti Sosial), Personal Story (Cerita Pribadi), dan Promotional (Promosi). Pastikan pilar ini disesuaikan dengan personal branding yang telah dibangun, **menonjolkan keunikan saya**, dengan memberikan sentuhan terkait niche pada penyebutan pilar utama.", CHAR(10), "> Tambahkan beberapa pilar lagi sebagai tambahan referensi untuk lebih banyak pilihan.", CHAR(10), CHAR(10), "Sertakan juga insight tentang:", CHAR(10), "- Kenapa pilar konten ini penting untuk membangun otoritas di niche tersebut.", CHAR(10), "- Bagaimana pilar konten ini bisa membantu audiens dan menyelesaikan masalah mereka.", CHAR(10), "- **Bagaimana setiap pilar dapat mendorong interaksi, membangun komunitas, dan mendukung tujuan monetisasi saya (misalnya, mendorong ke kelas/webinar).**", CHAR(10), "- Format yang cocok untuk menyampaikan konten dari masing-masing pilar (misalnya: video pendek / panjang, carousel, thread, dll.).", CHAR(10), CHAR(10), "Pastikan outputnya:", CHAR(10), "✔ Tidak terbatas pada jumlah tertentu, buat sebanyak mungkin agar bisa dipilih sesuai kebutuhan.", CHAR(10), "✔ Mudah dikembangkan menjadi strategi konten jangka panjang.", CHAR(10), "✔ Relevan dengan tren industri di bidang '", C2, "' serta selaras dengan target audiens saya.", CHAR(10), "✔ Membantu saya membangun personal branding yang kuat di bidang ini.", CHAR(10), "✔ **Memiliki potensi untuk membangun koneksi emosional dan loyalitas audiens.**", CHAR(10), CHAR(10), "Sajikan hasilnya dalam format tabel yang jelas, dengan kolom 'Content Pillar DNA' dan 'Deskripsi' untuk setiap pilar. Jika ada insight tambahan atau rekomendasi pengembangan, tambahkan untuk memperkaya strategi saya."), "")
B21: Klik atau Copas ke ChatGPT 👉🏻 | C21: Link Prompt
C22: =IF(C20<>"", IF(LEN("https://chatgpt.com/?prompt=" & SUBSTITUTE(SUBSTITUTE(C20, " ", "+"), "&", "dan")) <= 255, HYPERLINK("https://chatgpt.com/?prompt=" & SUBSTITUTE(SUBSTITUTE(C20, " ", "+"), "&", "dan") & "&force-refresh=true", "👉 Klik untuk Generate Content Pillar! 🔥"), "👉 Silakan copas Cell C20 manual & paste ke ChatGPT/Gemini! (Teks terlalu panjang untuk diklik di Excel) 🔥"), "")
C23: Kalau mau pakai AI lain bisa, tinggal copas aja promptnya dari ChatGPT!
B25: Isi Content Pillar-mu dari hasil generate AI, ingat untuk tetap menyesuaikan, jangan telan mentah-mentah 👉🏻 | C25: Tempatkan Hasil Generate Berdasarkan Jawaban Kamu di Kolom Bawah
C26: Content Pillar DNA | E26: Deskripsi
C27: Opportunity Content (Informasi) | E27: Topik: Update peluang beasiswa, lomba, event, exchange, volunteer, internship, bootcamp, dan program anak muda. Sub-topik: deadline, benefit, eligibility, cara daftar, reminder penting. Kenapa penting: Menjadi sumber peluang utama yang paling cepat dan relevan. Manfaat audiens: Hemat waktu cari info dan nggak kelewat kesempatan bagus. Interaksi: Ajak audiens save, share, dan komen kategori peluang yang dicari. Format: Carousel roundup, reels update, story reminder.
C28: Self Development (Leadership & Growth) | E28: Topik: Leadership, mindset, public speaking, networking, discipline, productivity, dan soft skill buat anak muda. Sub-topik: habit building, komunikasi, percaya diri, manajemen waktu, growth mindset. Kenapa penting: Bantu audiens berkembang jadi versi terbaik dirinya. Manfaat audiens: Lebih siap menghadapi kuliah, organisasi, kompetisi, dan karier. Interaksi: Mini challenge, refleksi, dan self-assessment. Format: Carousel step by step, reels tips cepat, thread edukatif.
C29: Educational & Career Insight | E29: Topik: Wawasan kampus, karier, CV, interview, LinkedIn, dan realita dunia kerja. Sub-topik: kesalahan umum mahasiswa, cara bikin profil lebih standout, career prep. Kenapa penting: Audiens butuh insight yang praktis dan relevan buat masa depan. Manfaat audiens: Lebih paham langkah strategis untuk bangun portofolio dan karier. Interaksi: Saveable tips, Q&A, dan diskusi pengalaman. Format: Carousel checklist, reels edukasi, post insight.
C30: Achievement & Ambition Lifestyle | E30: Topik: Gaya hidup anak muda ambis, aktif, berkembang, dan punya value. Sub-topik: rutinitas produktif, goal setting, konsistensi, celebration kecil, progress story. Kenapa penting: Membentuk citra Leaders ID sebagai ruang buat anak muda yang mau naik level. Manfaat audiens: Termotivasi untuk bergerak dan menjaga ritme growth. Interaksi: Relatable post, komentar progress, dan share milestone. Format: Carousel reflektif, reels motivasi, single image statement.
C31: Success Stories & Community Proof | E31: Topik: Kisah sukses, testimoni, dan perjalanan anak muda yang berkembang lewat peluang yang dibagikan. Sub-topik: before-after, lessons learned, behind the scenes, impact cerita nyata. Kenapa penting: Menumbuhkan trust dan bukti bahwa konten Leaders ID benar-benar berguna. Manfaat audiens: Punya role model dan referensi nyata untuk ikut langkah serupa. Interaksi: Ajak audiens share target mereka dan ceritakan progress. Format: Carousel storytelling, reels interview, quote post.
C32: Beasiswa & Global Opportunities | E32: Topik: Peluang beasiswa, exchange, conference, bootcamp, fellowship, dan program fully funded. Sub-topik: syarat, deadline, benefit, cara daftar, reminder penting. Kenapa penting: Memperluas akses audiens ke kesempatan belajar dan berkembang. Manfaat audiens: Nemu peluang yang relevan untuk skill, jaringan, dan karier. Interaksi: Save, share, dan request peluang sesuai kategori. Format: Carousel listicle, roundup mingguan, story reminder.
C33: Portfolio & Personal Branding | E33: Topik: Cara mengubah pengalaman jadi nilai tambah di CV, LinkedIn, dan portofolio. Sub-topik: achievement writing, project showcase, personal branding, dokumentasi karya. Kenapa penting: Bikin peluang yang didapat punya dampak jangka panjang. Manfaat audiens: Lebih siap untuk magang, organisasi, dan dunia kerja. Interaksi: Template, checklist, dan contoh before-after profil. Format: Carousel template, post edukasi, mini guide.
C34: Productivity & Mindset | E34: Topik: Mindset, kebiasaan, dan sistem kerja yang bantu audiens tetap konsisten. Sub-topik: manajemen waktu, fokus, anti-burnout, disiplin, self-confidence. Kenapa penting: Sisi mental sering jadi pembeda antara yang maju dan yang berhenti. Manfaat audiens: Bantu audiens tetap jalan walau prosesnya panjang. Interaksi: Cerita relate, polling, dan komentar pengalaman pribadi. Format: Carousel reflektif, reels motivasi, thread mindset.

Sheet SCRIPT GENERATOR
B1: Content Pillar Kamu dari Sheet Sebelumnya Otomatis Terisi di Kolom Berikut 👉🏻 | C1: Content Pillar | D1: Deskripsi | L1: Penjelasan Singkat (Bisa Kamu Sesuaikan Berdasarkan Niche)
C2: ='CONTENT PILLAR MAPPING'!C27 | D2: ='CONTENT PILLAR MAPPING'!E27 | M2: Nilai Tambah
C3: ='CONTENT PILLAR MAPPING'!C28 | D3: ='CONTENT PILLAR MAPPING'!E28 | L3: 1 | M3: Edukasi/Wawasan: Memberikan pengetahuan baru atau pemahaman mendalam.
C4: ='CONTENT PILLAR MAPPING'!C29 | D4: ='CONTENT PILLAR MAPPING'!E29 | L4: 2 | M4: Solusi Praktis: Memberikan tips atau langkah-langkah yang bisa langsung diterapkan.
C5: ='CONTENT PILLAR MAPPING'!C30 | D5: ='CONTENT PILLAR MAPPING'!E30 | L5: 3 | M5: Inspirasi/Motivasi: Mendorong audiens untuk bertindak atau percaya diri.
C6: ='CONTENT PILLAR MAPPING'!C31 | D6: ='CONTENT PILLAR MAPPING'!E29 | L6: 4 | M6: Hiburan/Relaksasi: Menyediakan konten yang menyenangkan dan menghibur.
E7: =IF(AND(C8<>"", E8<>"", 'CONTENT PILLAR MAPPING'!C2<>"", 'CONTENT PILLAR MAPPING'!E2<>"", 'CONTENT PILLAR MAPPING'!F2<>"", 'CONTENT PILLAR MAPPING'!C5<>"", 'CONTENT PILLAR MAPPING'!C10<>"", 'CONTENT PILLAR MAPPING'!D10<>"", 'CONTENT PILLAR MAPPING'!E10<>"", 'CONTENT PILLAR MAPPING'!D18<>"", 'CONTENT PILLAR MAPPING'!D19<>""), CONCATENATE( "Sebagai seorang dengan niche utama '", 'CONTENT PILLAR MAPPING'!C2, "', spesifik kategori '", 'CONTENT PILLAR MAPPING'!E2, "', dan super spesifik '", 'CONTENT PILLAR MAPPING'!F2, "', yang ingin dikenal sebagai '", 'CONTENT PILLAR MAPPING'!C5, "'.", CHAR(10), CHAR(10), "Saya memiliki Tone of Voice: '", 'CONTENT PILLAR MAPPING'!C10, "', Brand Archetype: '", 'CONTENT PILLAR MAPPING'!D10, "', dan Deskripsi Gaya Komunikasi: '", 'CONTENT PILLAR MAPPING'!E10, "'.", CHAR(10), CHAR(10), "Target audiens saya adalah: '", 'CONTENT PILLAR MAPPING'!D18, "', dengan segmentasi audiens: '", 'CONTENT PILLAR MAPPING'!D19, "'.", CHAR(10), CHAR(10), "Mohon buatkan daftar ide konten yang lengkap, kreatif, dan strategis untuk akun media sosial saya. Fokus utama dari ide konten ini adalah pilar '", C8, "'.", CHAR(10), CHAR(10), "Aku ingin daftar ide konten ini mencakup:", CHAR(10), "- Ide-ide spesifik yang bisa langsung dieksekusi, yang relevan dengan tren terkini dan membedakan saya dari kompetitor.", CHAR(10), "- Sudut pandang yang fresh dan unik.", CHAR(10), "- Gambaran singkat tentang kontennya, potensi viral, dan insight mengapa ide ini kuat.", CHAR(10), CHAR(10), "Pastikan outputnya:", CHAR(10), "✔ Berikan sebanyak ", E8, " pilihan ide, agar bisa dipilih sesuai kebutuhan.", CHAR(10), "✔ Kreatif, menarik, inovatif, dan punya potensi viral sesuai tren terkini.", CHAR(10), "✔ Bisa dikembangkan menjadi strategi konten jangka panjang.", CHAR(10), "✔ Sangat relevan dengan target audiens saya (", 'CONTENT PILLAR MAPPING'!D18, ", khusus ", 'CONTENT PILLAR MAPPING'!D19, ") dan membantu mereka menyelesaikan masalah atau mencapai tujuan mereka.", CHAR(10), "✔ Membantuku membangun personal branding yang kuat dan sustainable, sesuai dengan Positioning saya sebagai '", 'CONTENT PILLAR MAPPING'!C5, "'.", CHAR(10), "✔ Kemas dalam bentuk tabel agar rapi, mudah di baca dan dipahami, dengan kolom 'Topik Konten', 'Pilar', 'Format Ideal', 'Platform Ideal', dan 'Gambaran Singkat Ide'." ), "") | L7: 5 | M7: Validasi/Bukti Sosial: Menunjukkan hasil nyata atau testimoni.
B8: Pilih Pillar yang Ingin Kamu Cari Ide Kontennya 👉🏻 | C8: Opportunity Content (Informasi) | D8: Mau Bikin Berapa Ide Konten? 👉🏻 | E8: 10 | F8: =IF(E7<>"", HYPERLINK("https://chatgpt.com/?prompt=" & SUBSTITUTE(SUBSTITUTE(E7, " ", "+"), "&", "dan") & "&force-refresh=true&timestamp=" & TEXT(NOW(), "yyyymmddhhmmss"), "👉 Klik untuk Generate Ide Konten! 🔥"), "") | L8: 6 | M8: Hemat Waktu/Efisiensi: Memberikan cara untuk menyelesaikan sesuatu lebih cepat.
H9: =IF(AND(B12<>"", C12<>"", D12<>"", E12<>"", F12<>"", G12<>"", J12<>"", 'CONTENT PILLAR MAPPING'!C2<>"", 'CONTENT PILLAR MAPPING'!E2<>"", 'CONTENT PILLAR MAPPING'!F2<>"", 'CONTENT PILLAR MAPPING'!C5<>"", 'CONTENT PILLAR MAPPING'!C10<>"", 'CONTENT PILLAR MAPPING'!D10<>"", 'CONTENT PILLAR MAPPING'!E10<>"", 'CONTENT PILLAR MAPPING'!D18<>"", 'CONTENT PILLAR MAPPING'!D19<>""), CONCATENATE( "Sebagai seorang top konten kreator dengan niche utama '", 'CONTENT PILLAR MAPPING'!C2, "', spesifik kategori '", 'CONTENT PILLAR MAPPING'!E2, "', dan super spesifik '", 'CONTENT PILLAR MAPPING'!F2, "', yang dikenal sebagai '", 'CONTENT PILLAR MAPPING'!C5, "'.", CHAR(10), "Saya memiliki Tone of Voice: '", 'CONTENT PILLAR MAPPING'!C10, "', Brand Archetype: '", 'CONTENT PILLAR MAPPING'!D10, "', dan Deskripsi Gaya Komunikasi: '", 'CONTENT PILLAR MAPPING'!E10, "'.", CHAR(10), "Target audiens saya adalah: '", 'CONTENT PILLAR MAPPING'!D18, "', dengan segmentasi audiens: '", 'CONTENT PILLAR MAPPING'!D19, "'.", CHAR(10), CHAR(10), "Mohon buatkan script konten yang **sangat powerful, menarik, inovatif, dan siap pakai** dengan judul ide '", B12, "'.", CHAR(10), "Konten ini memiliki pilar '", C12, "', nilai tambah utama '", F12, "', dan akan menggunakan storytelling framework '", G12, "'.", CHAR(10), "Gambaran singkat ide kontennya adalah: '", J12, "'.", CHAR(10), "Konten ini akan diunggah di platform '", E12, "' dengan format '", D12, "'.", CHAR(10), CHAR(10), "Script harus mencakup:", CHAR(10), "- Ide visual konten yang kreatif dan sangat detail, termasuk saran untuk setiap panel (jika carousel) atau *scene* (jika video), dan elemen visual penunjang untuk format yang dipilih.", CHAR(10), "- Script hook yang sangat kuat, memancing rasa penasaran, relevan dengan audiens, dan selaras dengan storytelling framework.", CHAR(10), "- Isi konten utama yang informatif, *engaging*, **memecahkan masalah audiens secara langsung, dan secara subtil menonjolkan keunikan saya sebagai '", 'CONTENT PILLAR MAPPING'!C5, "'.** Sesuaikan dengan gaya komunikasi saya, dengan fokus pada nilai tambah '", F12, "'.", CHAR(10), "- Call-to-Action (CTA) yang bervariatif, jelas, dan mendorong interaksi atau langkah selanjutnya (misalnya: follow, komen, share, save, kunjungi link di bio, daftar webinar, beli produk).", CHAR(10), "- Caption lengkap yang meliputi framework copywriting (Headline yang menarik, Bodycopy yang persuasif, dan CTA lagi di dalamnya), serta hashtag yang relevan dan trending.", CHAR(10), CHAR(10), "**Penting:** Untuk pilihan pertama dari script yang Anda hasilkan, mohon kembangkan menjadi **satu script yang paling detail dan komprehensif**, seolah-olah siap digunakan untuk produksi, dengan semua elemen visual dan naratif yang sangat jelas. Berikan 3"&"-5 pilihan script yang bervariasi, unik, dan siap pakai.", CHAR(10), "Pastikan outputnya:", CHAR(10), "✔ Kreatif, menarik, inovatif, dan punya potensi viral sesuai tren terkini.", CHAR(10), "✔ Sangat relevan dengan target audiens saya (", 'CONTENT PILLAR MAPPING'!D18, ", khusus ", 'CONTENT PILLAR MAPPING'!D19, ") dan membantu mereka menyelesaikan masalah atau mencapai tujuan mereka.", CHAR(10), "✔ Membantuku membangun personal branding yang kuat dan sustainable, sesuai dengan Positioning saya sebagai '", 'CONTENT PILLAR MAPPING'!C5, "' dan Brand Archetype '", 'CONTENT PILLAR MAPPING'!D10, "'.", CHAR(10), "✔ Kemas dalam bentuk tabel agar rapi, mudah di baca dan dipahami, dengan kolom 'Judul Konten', 'Pilar', 'Format', 'Draft Script', 'CTA', 'Saran Visual', dan 'Full Caption'. (Kosongkan kolom Link Prompt jika ada)." ), "") | L9: 7 | M9: Conversion/Jualan: Konten Promo, Penawaran yang tujuannya untuk jualan
B10: 👇🏻 Bank Ide Konten (Masukkan Ide-Ide Hasil Generate AI yang kamu Anggap Oke) 👇🏻 | L10: 8 | M10: Perspektif Baru: Menawarkan sudut pandang yang berbeda atau unik.
B11: Ide (Topik Konten) | C11: Pillar | D11: Format | E11: Platform | F11: Nilai Tambah | G11: Storytelling | H11: Link Prompt | I11: Link Template Script | J11: Gambaran Singkat Ide | L11: 9 | M11: Koneksi/Komunitas: Membangun rasa kebersamaan dan interaksi.
B12: 5 Red Flags Lomba Abal-Abal yang Harus Kamu Hindari | C12: Opportunity Content (Informasi) | D12: Carousel | E12: Instagram | F12: Informasi | G12: Problem-Solution | H12: =IF(H9<>"",HYPERLINK("https://chatgpt.com/?q="&ENCODEURL(H9),"👉 Klik untuk Generate Script! 🔥"),"") | I12: Template - Skrip Konten Carousels & Reels.docx | J12: Konten edukatif yang bantu audiens mengenali tanda lomba mencurigakan sebelum buang uang, waktu, dan karya. | L12: 10 | M12: Peringatan/Mitigasi Risiko: Memberi tahu audiens apa yang harus dihindari atau cara mengurangi risiko.
B13: Jangan Asal Daftar, Pakai 5 Filter Ini Buat Pilih Lomba yang Worth It | C13: Opportunity Content (Informasi) | D13: Carousel | E13: Instagram | F13: Solusi | G13: Problem-Solution | H13: 👉 Klik untuk Generate Script! 🔥 | I13: Template - Skrip Konten Carousels & Reels.docx | J13: Konten filter praktis untuk bantu audiens menilai apakah sebuah lomba layak diikuti atau sebaiknya dilewatkan. | K13: =IF(AND(B13<>"", C13<>"", D13<>"", E13<>"", F13<>"", G13<>"", J13<>"", 'CONTENT PILLAR MAPPING'!C2<>"", 'CONTENT PILLAR MAPPING'!E2<>"", 'CONTENT PILLAR MAPPING'!F2<>"", 'CONTENT PILLAR MAPPING'!C5<>"", 'CONTENT PILLAR MAPPING'!C10<>"", 'CONTENT PILLAR MAPPING'!D10<>"", 'CONTENT PILLAR MAPPING'!E10<>"", 'CONTENT PILLAR MAPPING'!D18<>"", 'CONTENT PILLAR MAPPING'!D19<>""), CONCATENATE( "Sebagai seorang top konten kreator dengan niche utama '", 'CONTENT PILLAR MAPPING'!C2, "', spesifik kategori '", 'CONTENT PILLAR MAPPING'!E2, "', dan super spesifik '", 'CONTENT PILLAR MAPPING'!F2, "', yang dikenal sebagai '", 'CONTENT PILLAR MAPPING'!C5, "'.", CHAR(10), "Saya memiliki Tone of Voice: '", 'CONTENT PILLAR MAPPING'!C10, "', Brand Archetype: '", 'CONTENT PILLAR MAPPING'!D10, "', dan Deskripsi Gaya Komunikasi: '", 'CONTENT PILLAR MAPPING'!E10, "'.", CHAR(10), "Target audiens saya adalah: '", 'CONTENT PILLAR MAPPING'!D18, "', dengan segmentasi audiens: '", 'CONTENT PILLAR MAPPING'!D19, "'.", CHAR(10), CHAR(10), "Mohon buatkan script konten yang **sangat powerful, menarik, inovatif, dan siap pakai** dengan judul ide '", B13, "'.", CHAR(10), "Konten ini memiliki pilar '", C13, "', nilai tambah utama '", F13, "', dan akan menggunakan storytelling framework '", G13, "'.", CHAR(10), "Gambaran singkat ide kontennya adalah: '", J13, "'.", CHAR(10), "Konten ini akan diunggah di platform '", E13, "' dengan format '", D13, "'.", CHAR(10), CHAR(10), "Script harus mencakup:", CHAR(10), "- Ide visual konten yang kreatif dan sangat detail, termasuk saran untuk setiap panel (jika carousel) atau *scene* (jika video), dan elemen visual penunjang untuk format yang dipilih.", CHAR(10), "- Script hook yang sangat kuat, memancing rasa penasaran, relevan dengan audiens, dan selaras dengan storytelling framework.", CHAR(10), "- Isi konten utama yang informatif, *engaging*, **memecahkan masalah audiens secara langsung, dan secara subtil menonjolkan keunikan saya sebagai '", 'CONTENT PILLAR MAPPING'!C5, "'.** Sesuaikan dengan gaya komunikasi saya, dengan fokus pada nilai tambah '", F13, "'.", CHAR(10), "- Call-to-Action (CTA) yang bervariatif, jelas, dan mendorong interaksi atau langkah selanjutnya (misalnya: follow, komen, share, save, kunjungi link di bio, daftar webinar, beli produk).", CHAR(10), "- Caption lengkap yang meliputi framework copywriting (Headline yang menarik, Bodycopy yang persuasif, dan CTA lagi di dalamnya), serta hashtag yang relevan dan trending.", CHAR(10), CHAR(10), "**Penting:** Untuk pilihan pertama dari script yang Anda hasilkan, mohon kembangkan menjadi **satu script yang paling detail dan komprehensif**, seolah-olah siap digunakan untuk produksi, dengan semua elemen visual dan naratif yang sangat jelas. Berikan 3"&"-5 pilihan script yang bervariasi, unik, dan siap pakai.", CHAR(10), "Pastikan outputnya:", CHAR(10), "✔ Kreatif, menarik, inovatif, dan punya potensi viral sesuai tren terkini.", CHAR(10), "✔ Sangat relevan dengan target audiens saya (", 'CONTENT PILLAR MAPPING'!D18, ", khusus ", 'CONTENT PILLAR MAPPING'!D19, ") dan membantu mereka menyelesaikan masalah atau mencapai tujuan mereka.", CHAR(10), "✔ Membantuku membangun personal branding yang kuat dan sustainable, sesuai dengan Positioning saya sebagai '", 'CONTENT PILLAR MAPPING'!C5, "' dan Brand Archetype '", 'CONTENT PILLAR MAPPING'!D10, "'.", CHAR(10), "✔ Kemas dalam bentuk tabel agar rapi, mudah di baca dan dipahami, dengan kolom 'Judul Konten', 'Pilar', 'Format', 'Draft Script', 'CTA', 'Saran Visual', dan 'Full Caption'. (Kosongkan kolom Link Prompt jika ada)." ), "")
B14: 5 Tanda Lomba Ini Cocok Buat Kamu Ikuti, Bukan Cuma FOMO | C14: Opportunity Content (Informasi) | D14: Carousel | E14: Instagram | F14: Perspektif Baru | G14: The Aha Moment | H14: =IF(H9<>"",HYPERLINK("https://chatgpt.com/?q="&ENCODEURL(H9),"👉 Klik untuk Generate Script! 🔥"),"") | I14: Template - Skrip Konten Carousels & Reels.docx | J14: Konten yang menggeser pola pikir dari asal ikut karena ramai menjadi ikut lomba secara strategis dan relevan. | K14: =IF(AND(B14<>"", C14<>"", D14<>"", E14<>"", F14<>"", G14<>"", J14<>"", 'CONTENT PILLAR MAPPING'!C2<>"", 'CONTENT PILLAR MAPPING'!E2<>"", 'CONTENT PILLAR MAPPING'!F2<>"", 'CONTENT PILLAR MAPPING'!C5<>"", 'CONTENT PILLAR MAPPING'!C10<>"", 'CONTENT PILLAR MAPPING'!D10<>"", 'CONTENT PILLAR MAPPING'!E10<>"", 'CONTENT PILLAR MAPPING'!D18<>"", 'CONTENT PILLAR MAPPING'!D19<>""), CONCATENATE( "Sebagai seorang top konten kreator dengan niche utama '", 'CONTENT PILLAR MAPPING'!C2, "', spesifik kategori '", 'CONTENT PILLAR MAPPING'!E2, "', dan super spesifik '", 'CONTENT PILLAR MAPPING'!F2, "', yang dikenal sebagai '", 'CONTENT PILLAR MAPPING'!C5, "'.", CHAR(10), "Saya memiliki Tone of Voice: '", 'CONTENT PILLAR MAPPING'!C10, "', Brand Archetype: '", 'CONTENT PILLAR MAPPING'!D10, "', dan Deskripsi Gaya Komunikasi: '", 'CONTENT PILLAR MAPPING'!E10, "'.", CHAR(10), "Target audiens saya adalah: '", 'CONTENT PILLAR MAPPING'!D18, "', dengan segmentasi audiens: '", 'CONTENT PILLAR MAPPING'!D19, "'.", CHAR(10), CHAR(10), "Mohon buatkan script konten yang **sangat powerful, menarik, inovatif, dan siap pakai** dengan judul ide '", B14, "'.", CHAR(10), "Konten ini memiliki pilar '", C14, "', nilai tambah utama '", F14, "', dan akan menggunakan storytelling framework '", G14, "'.", CHAR(10), "Gambaran singkat ide kontennya adalah: '", J14, "'.", CHAR(10), "Konten ini akan diunggah di platform '", E14, "' dengan format '", D14, "'.", CHAR(10), CHAR(10), "Script harus mencakup:", CHAR(10), "- Ide visual konten yang kreatif dan sangat detail, termasuk saran untuk setiap panel (jika carousel) atau *scene* (jika video), dan elemen visual penunjang untuk format yang dipilih.", CHAR(10), "- Script hook yang sangat kuat, memancing rasa penasaran, relevan dengan audiens, dan selaras dengan storytelling framework.", CHAR(10), "- Isi konten utama yang informatif, *engaging*, **memecahkan masalah audiens secara langsung, dan secara subtil menonjolkan keunikan saya sebagai '", 'CONTENT PILLAR MAPPING'!C5, "'.** Sesuaikan dengan gaya komunikasi saya, dengan fokus pada nilai tambah '", F14, "'.", CHAR(10), "- Call-to-Action (CTA) yang bervariatif, jelas, dan mendorong interaksi atau langkah selanjutnya (misalnya: follow, komen, share, save, kunjungi link di bio, daftar webinar, beli produk).", CHAR(10), "- Caption lengkap yang meliputi framework copywriting (Headline yang menarik, Bodycopy yang persuasif, dan CTA lagi di dalamnya), serta hashtag yang relevan dan trending.", CHAR(10), CHAR(10), "**Penting:** Untuk pilihan pertama dari script yang Anda hasilkan, mohon kembangkan menjadi **satu script yang paling detail dan komprehensif**, seolah-olah siap digunakan untuk produksi, dengan semua elemen visual dan naratif yang sangat jelas. Berikan 3"&"-5 pilihan script yang bervariasi, unik, dan siap pakai.", CHAR(10), "Pastikan outputnya:", CHAR(10), "✔ Kreatif, menarik, inovatif, dan punya potensi viral sesuai tren terkini.", CHAR(10), "✔ Sangat relevan dengan target audiens saya (", 'CONTENT PILLAR MAPPING'!D18, ", khusus ", 'CONTENT PILLAR MAPPING'!D19, ") dan membantu mereka menyelesaikan masalah atau mencapai tujuan mereka.", CHAR(10), "✔ Membantuku membangun personal branding yang kuat dan sustainable, sesuai dengan Positioning saya sebagai '", 'CONTENT PILLAR MAPPING'!C5, "' dan Brand Archetype '", 'CONTENT PILLAR MAPPING'!D10, "'.", CHAR(10), "✔ Kemas dalam bentuk tabel agar rapi, mudah di baca dan dipahami, dengan kolom 'Judul Konten', 'Pilar', 'Format', 'Draft Script', 'CTA', 'Saran Visual', dan 'Full Caption'. (Kosongkan kolom Link Prompt jika ada)." ), "") | M14: Storytelling
B15: Cara Baca Brief Lomba dalam 5 Menit Biar Tahu Layak Diikutin atau Nggak | C15: Opportunity Content (Informasi) | D15: Carousel | E15: Instagram | F15: Edukasi/Wawasan | G15: Problem-Solution | H15: =IF(H9<>"",HYPERLINK("https://chatgpt.com/?q="&ENCODEURL(H9),"👉 Klik untuk Generate Script! 🔥"),"") | I15: Template - Skrip Konten Carousels & Reels.docx | J15: Konten step-by-step untuk bantu audiens membaca brief lebih cepat dan lebih kritis sebelum daftar. | K15: =IF(AND(B15<>"", C15<>"", D15<>"", E15<>"", F15<>"", G15<>"", J15<>"", 'CONTENT PILLAR MAPPING'!C2<>"", 'CONTENT PILLAR MAPPING'!E2<>"", 'CONTENT PILLAR MAPPING'!F2<>"", 'CONTENT PILLAR MAPPING'!C5<>"", 'CONTENT PILLAR MAPPING'!C10<>"", 'CONTENT PILLAR MAPPING'!D10<>"", 'CONTENT PILLAR MAPPING'!E10<>"", 'CONTENT PILLAR MAPPING'!D18<>"", 'CONTENT PILLAR MAPPING'!D19<>""), CONCATENATE( "Sebagai seorang top konten kreator dengan niche utama '", 'CONTENT PILLAR MAPPING'!C2, "', spesifik kategori '", 'CONTENT PILLAR MAPPING'!E2, "', dan super spesifik '", 'CONTENT PILLAR MAPPING'!F2, "', yang dikenal sebagai '", 'CONTENT PILLAR MAPPING'!C5, "'.", CHAR(10), "Saya memiliki Tone of Voice: '", 'CONTENT PILLAR MAPPING'!C10, "', Brand Archetype: '", 'CONTENT PILLAR MAPPING'!D10, "', dan Deskripsi Gaya Komunikasi: '", 'CONTENT PILLAR MAPPING'!E10, "'.", CHAR(10), "Target audiens saya adalah: '", 'CONTENT PILLAR MAPPING'!D18, "', dengan segmentasi audiens: '", 'CONTENT PILLAR MAPPING'!D19, "'.", CHAR(10), CHAR(10), "Mohon buatkan script konten yang **sangat powerful, menarik, inovatif, dan siap pakai** dengan judul ide '", B15, "'.", CHAR(10), "Konten ini memiliki pilar '", C15, "', nilai tambah utama '", F15, "', dan akan menggunakan storytelling framework '", G15, "'.", CHAR(10), "Gambaran singkat ide kontennya adalah: '", J15, "'.", CHAR(10), "Konten ini akan diunggah di platform '", E15, "' dengan format '", D15, "'.", CHAR(10), CHAR(10), "Script harus mencakup:", CHAR(10), "- Ide visual konten yang kreatif dan sangat detail, termasuk saran untuk setiap panel (jika carousel) atau *scene* (jika video), dan elemen visual penunjang untuk format yang dipilih.", CHAR(10), "- Script hook yang sangat kuat, memancing rasa penasaran, relevan dengan audiens, dan selaras dengan storytelling framework.", CHAR(10), "- Isi konten utama yang informatif, *engaging*, **memecahkan masalah audiens secara langsung, dan secara subtil menonjolkan keunikan saya sebagai '", 'CONTENT PILLAR MAPPING'!C5, "'.** Sesuaikan dengan gaya komunikasi saya, dengan fokus pada nilai tambah '", F15, "'.", CHAR(10), "- Call-to-Action (CTA) yang bervariatif, jelas, dan mendorong interaksi atau langkah selanjutnya (misalnya: follow, komen, share, save, kunjungi link di bio, daftar webinar, beli produk).", CHAR(10), "- Caption lengkap yang meliputi framework copywriting (Headline yang menarik, Bodycopy yang persuasif, dan CTA lagi di dalamnya), serta hashtag yang relevan dan trending.", CHAR(10), CHAR(10), "**Penting:** Untuk pilihan pertama dari script yang Anda hasilkan, mohon kembangkan menjadi **satu script yang paling detail dan komprehensif**, seolah-olah siap digunakan untuk produksi, dengan semua elemen visual dan naratif yang sangat jelas. Berikan 3"&"-5 pilihan script yang bervariasi, unik, dan siap pakai.", CHAR(10), "Pastikan outputnya:", CHAR(10), "✔ Kreatif, menarik, inovatif, dan punya potensi viral sesuai tren terkini.", CHAR(10), "✔ Sangat relevan dengan target audiens saya (", 'CONTENT PILLAR MAPPING'!D18, ", khusus ", 'CONTENT PILLAR MAPPING'!D19, ") dan membantu mereka menyelesaikan masalah atau mencapai tujuan mereka.", CHAR(10), "✔ Membantuku membangun personal branding yang kuat dan sustainable, sesuai dengan Positioning saya sebagai '", 'CONTENT PILLAR MAPPING'!C5, "' dan Brand Archetype '", 'CONTENT PILLAR MAPPING'!D10, "'.", CHAR(10), "✔ Kemas dalam bentuk tabel agar rapi, mudah di baca dan dipahami, dengan kolom 'Judul Konten', 'Pilar', 'Format', 'Draft Script', 'CTA', 'Saran Visual', dan 'Full Caption'. (Kosongkan kolom Link Prompt jika ada)." ), "") | L15: 1 | M15: Zero to Hero: Perjalanan karakter dari kesulitan menuju kesuksesan.
B16: 6 Jenis Lomba yang Paling Worth Buat Upgrade CV Anak Muda | C16: Opportunity Content (Informasi) | D16: Carousel | E16: Instagram | F16: Edukasi/Wawasan | G16: Before-After | H16: =IF(H9<>"",HYPERLINK("https://chatgpt.com/?q="&ENCODEURL(H9),"👉 Klik untuk Generate Script! 🔥"),"") | I16: Template - Skrip Konten Carousels & Reels.docx | J16: Konten edukatif yang membandingkan jenis lomba berdasarkan dampaknya ke CV, portofolio, dan growth jangka panjang. | K16: =IF(AND(B16<>"", C16<>"", D16<>"", E16<>"", F16<>"", G16<>"", J16<>"", 'CONTENT PILLAR MAPPING'!C2<>"", 'CONTENT PILLAR MAPPING'!E2<>"", 'CONTENT PILLAR MAPPING'!F2<>"", 'CONTENT PILLAR MAPPING'!C5<>"", 'CONTENT PILLAR MAPPING'!C10<>"", 'CONTENT PILLAR MAPPING'!D10<>"", 'CONTENT PILLAR MAPPING'!E10<>"", 'CONTENT PILLAR MAPPING'!D18<>"", 'CONTENT PILLAR MAPPING'!D19<>""), CONCATENATE( "Sebagai seorang top konten kreator dengan niche utama '", 'CONTENT PILLAR MAPPING'!C2, "', spesifik kategori '", 'CONTENT PILLAR MAPPING'!E2, "', dan super spesifik '", 'CONTENT PILLAR MAPPING'!F2, "', yang dikenal sebagai '", 'CONTENT PILLAR MAPPING'!C5, "'.", CHAR(10), "Saya memiliki Tone of Voice: '", 'CONTENT PILLAR MAPPING'!C10, "', Brand Archetype: '", 'CONTENT PILLAR MAPPING'!D10, "', dan Deskripsi Gaya Komunikasi: '", 'CONTENT PILLAR MAPPING'!E10, "'.", CHAR(10), "Target audiens saya adalah: '", 'CONTENT PILLAR MAPPING'!D18, "', dengan segmentasi audiens: '", 'CONTENT PILLAR MAPPING'!D19, "'.", CHAR(10), CHAR(10), "Mohon buatkan script konten yang **sangat powerful, menarik, inovatif, dan siap pakai** dengan judul ide '", B16, "'.", CHAR(10), "Konten ini memiliki pilar '", C16, "', nilai tambah utama '", F16, "', dan akan menggunakan storytelling framework '", G16, "'.", CHAR(10), "Gambaran singkat ide kontennya adalah: '", J16, "'.", CHAR(10), "Konten ini akan diunggah di platform '", E16, "' dengan format '", D16, "'.", CHAR(10), CHAR(10), "Script harus mencakup:", CHAR(10), "- Ide visual konten yang kreatif dan sangat detail, termasuk saran untuk setiap panel (jika carousel) atau *scene* (jika video), dan elemen visual penunjang untuk format yang dipilih.", CHAR(10), "- Script hook yang sangat kuat, memancing rasa penasaran, relevan dengan audiens, dan selaras dengan storytelling framework.", CHAR(10), "- Isi konten utama yang informatif, *engaging*, **memecahkan masalah audiens secara langsung, dan secara subtil menonjolkan keunikan saya sebagai '", 'CONTENT PILLAR MAPPING'!C5, "'.** Sesuaikan dengan gaya komunikasi saya, dengan fokus pada nilai tambah '", F16, "'.", CHAR(10), "- Call-to-Action (CTA) yang bervariatif, jelas, dan mendorong interaksi atau langkah selanjutnya (misalnya: follow, komen, share, save, kunjungi link di bio, daftar webinar, beli produk).", CHAR(10), "- Caption lengkap yang meliputi framework copywriting (Headline yang menarik, Bodycopy yang persuasif, dan CTA lagi di dalamnya), serta hashtag yang relevan dan trending.", CHAR(10), CHAR(10), "**Penting:** Untuk pilihan pertama dari script yang Anda hasilkan, mohon kembangkan menjadi **satu script yang paling detail dan komprehensif**, seolah-olah siap digunakan untuk produksi, dengan semua elemen visual dan naratif yang sangat jelas. Berikan 3"&"-5 pilihan script yang bervariasi, unik, dan siap pakai.", CHAR(10), "Pastikan outputnya:", CHAR(10), "✔ Kreatif, menarik, inovatif, dan punya potensi viral sesuai tren terkini.", CHAR(10), "✔ Sangat relevan dengan target audiens saya (", 'CONTENT PILLAR MAPPING'!D18, ", khusus ", 'CONTENT PILLAR MAPPING'!D19, ") dan membantu mereka menyelesaikan masalah atau mencapai tujuan mereka.", CHAR(10), "✔ Membantuku membangun personal branding yang kuat dan sustainable, sesuai dengan Positioning saya sebagai '", 'CONTENT PILLAR MAPPING'!C5, "' dan Brand Archetype '", 'CONTENT PILLAR MAPPING'!D10, "'.", CHAR(10), "✔ Kemas dalam bentuk tabel agar rapi, mudah di baca dan dipahami, dengan kolom 'Judul Konten', 'Pilar', 'Format', 'Draft Script', 'CTA', 'Saran Visual', dan 'Full Caption'. (Kosongkan kolom Link Prompt jika ada)." ), "") | L16: 2 | M16: The Hero's Journey: Petualangan karakter menghadapi cobaan dan kembali dengan pelajaran.
B17: Kalau Baru Mau Mulai Ikut Lomba, Mulai dari Kategori Ini Dulu | C17: Opportunity Content (Informasi) | D17: Carousel | E17: Instagram | F17: Solusi | G17: Zero to Hero | H17: =IF(H9<>"",HYPERLINK("https://chatgpt.com/?q="&ENCODEURL(H9),"👉 Klik untuk Generate Script! 🔥"),"") | I17: Template - Skrip Konten Carousels & Reels.docx | J17: Konten beginner-friendly yang ngasih jalur masuk paling aman buat pemula yang baru mau mulai ikut lomba. | K17: =IF(AND(B17<>"", C17<>"", D17<>"", E17<>"", F17<>"", G17<>"", J17<>"", 'CONTENT PILLAR MAPPING'!C2<>"", 'CONTENT PILLAR MAPPING'!E2<>"", 'CONTENT PILLAR MAPPING'!F2<>"", 'CONTENT PILLAR MAPPING'!C5<>"", 'CONTENT PILLAR MAPPING'!C10<>"", 'CONTENT PILLAR MAPPING'!D10<>"", 'CONTENT PILLAR MAPPING'!E10<>"", 'CONTENT PILLAR MAPPING'!D18<>"", 'CONTENT PILLAR MAPPING'!D19<>""), CONCATENATE( "Sebagai seorang top konten kreator dengan niche utama '", 'CONTENT PILLAR MAPPING'!C2, "', spesifik kategori '", 'CONTENT PILLAR MAPPING'!E2, "', dan super spesifik '", 'CONTENT PILLAR MAPPING'!F2, "', yang dikenal sebagai '", 'CONTENT PILLAR MAPPING'!C5, "'.", CHAR(10), "Saya memiliki Tone of Voice: '", 'CONTENT PILLAR MAPPING'!C10, "', Brand Archetype: '", 'CONTENT PILLAR MAPPING'!D10, "', dan Deskripsi Gaya Komunikasi: '", 'CONTENT PILLAR MAPPING'!E10, "'.", CHAR(10), "Target audiens saya adalah: '", 'CONTENT PILLAR MAPPING'!D18, "', dengan segmentasi audiens: '", 'CONTENT PILLAR MAPPING'!D19, "'.", CHAR(10), CHAR(10), "Mohon buatkan script konten yang **sangat powerful, menarik, inovatif, dan siap pakai** dengan judul ide '", B17, "'.", CHAR(10), "Konten ini memiliki pilar '", C17, "', nilai tambah utama '", F17, "', dan akan menggunakan storytelling framework '", G17, "'.", CHAR(10), "Gambaran singkat ide kontennya adalah: '", J17, "'.", CHAR(10), "Konten ini akan diunggah di platform '", E17, "' dengan format '", D17, "'.", CHAR(10), CHAR(10), "Script harus mencakup:", CHAR(10), "- Ide visual konten yang kreatif dan sangat detail, termasuk saran untuk setiap panel (jika carousel) atau *scene* (jika video), dan elemen visual penunjang untuk format yang dipilih.", CHAR(10), "- Script hook yang sangat kuat, memancing rasa penasaran, relevan dengan audiens, dan selaras dengan storytelling framework.", CHAR(10), "- Isi konten utama yang informatif, *engaging*, **memecahkan masalah audiens secara langsung, dan secara subtil menonjolkan keunikan saya sebagai '", 'CONTENT PILLAR MAPPING'!C5, "'.** Sesuaikan dengan gaya komunikasi saya, dengan fokus pada nilai tambah '", F17, "'.", CHAR(10), "- Call-to-Action (CTA) yang bervariatif, jelas, dan mendorong interaksi atau langkah selanjutnya (misalnya: follow, komen, share, save, kunjungi link di bio, daftar webinar, beli produk).", CHAR(10), "- Caption lengkap yang meliputi framework copywriting (Headline yang menarik, Bodycopy yang persuasif, dan CTA lagi di dalamnya), serta hashtag yang relevan dan trending.", CHAR(10), CHAR(10), "**Penting:** Untuk pilihan pertama dari script yang Anda hasilkan, mohon kembangkan menjadi **satu script yang paling detail dan komprehensif**, seolah-olah siap digunakan untuk produksi, dengan semua elemen visual dan naratif yang sangat jelas. Berikan 3"&"-5 pilihan script yang bervariasi, unik, dan siap pakai.", CHAR(10), "Pastikan outputnya:", CHAR(10), "✔ Kreatif, menarik, inovatif, dan punya potensi viral sesuai tren terkini.", CHAR(10), "✔ Sangat relevan dengan target audiens saya (", 'CONTENT PILLAR MAPPING'!D18, ", khusus ", 'CONTENT PILLAR MAPPING'!D19, ") dan membantu mereka menyelesaikan masalah atau mencapai tujuan mereka.", CHAR(10), "✔ Membantuku membangun personal branding yang kuat dan sustainable, sesuai dengan Positioning saya sebagai '", 'CONTENT PILLAR MAPPING'!C5, "' dan Brand Archetype '", 'CONTENT PILLAR MAPPING'!D10, "'.", CHAR(10), "✔ Kemas dalam bentuk tabel agar rapi, mudah di baca dan dipahami, dengan kolom 'Judul Konten', 'Pilar', 'Format', 'Draft Script', 'CTA', 'Saran Visual', dan 'Full Caption'. (Kosongkan kolom Link Prompt jika ada)." ), "") | L17: 3 | M17: Problem-Solution: Mengidentifikasi masalah audiens dan menawarkan solusi.
B18: Sering Gugur di Awal? Bisa Jadi Kamu Salah Pilih Lomba dari Awal | C18: Opportunity Content (Informasi) | D18: Carousel | E18: Instagram | F18: Perspektif Baru | G18: False Star | H18: =IF(H9<>"",HYPERLINK("https://chatgpt.com/?q="&ENCODEURL(H9),"👉 Klik untuk Generate Script! 🔥"),"") | I18: Template - Skrip Konten Carousels & Reels.docx | J18: Konten problem-solution yang menunjukkan kalau kegagalan awal sering bermula dari salah memilih medan lomba. | K18: =IF(AND(B18<>"", C18<>"", D18<>"", E18<>"", F18<>"", G18<>"", J18<>"", 'CONTENT PILLAR MAPPING'!C2<>"", 'CONTENT PILLAR MAPPING'!E2<>"", 'CONTENT PILLAR MAPPING'!F2<>"", 'CONTENT PILLAR MAPPING'!C5<>"", 'CONTENT PILLAR MAPPING'!C10<>"", 'CONTENT PILLAR MAPPING'!D10<>"", 'CONTENT PILLAR MAPPING'!E10<>"", 'CONTENT PILLAR MAPPING'!D18<>"", 'CONTENT PILLAR MAPPING'!D19<>""), CONCATENATE( "Sebagai seorang top konten kreator dengan niche utama '", 'CONTENT PILLAR MAPPING'!C2, "', spesifik kategori '", 'CONTENT PILLAR MAPPING'!E2, "', dan super spesifik '", 'CONTENT PILLAR MAPPING'!F2, "', yang dikenal sebagai '", 'CONTENT PILLAR MAPPING'!C5, "'.", CHAR(10), "Saya memiliki Tone of Voice: '", 'CONTENT PILLAR MAPPING'!C10, "', Brand Archetype: '", 'CONTENT PILLAR MAPPING'!D10, "', dan Deskripsi Gaya Komunikasi: '", 'CONTENT PILLAR MAPPING'!E10, "'.", CHAR(10), "Target audiens saya adalah: '", 'CONTENT PILLAR MAPPING'!D18, "', dengan segmentasi audiens: '", 'CONTENT PILLAR MAPPING'!D19, "'.", CHAR(10), CHAR(10), "Mohon buatkan script konten yang **sangat powerful, menarik, inovatif, dan siap pakai** dengan judul ide '", B18, "'.", CHAR(10), "Konten ini memiliki pilar '", C18, "', nilai tambah utama '", F18, "', dan akan menggunakan storytelling framework '", G18, "'.", CHAR(10), "Gambaran singkat ide kontennya adalah: '", J18, "'.", CHAR(10), "Konten ini akan diunggah di platform '", E18, "' dengan format '", D18, "'.", CHAR(10), CHAR(10), "Script harus mencakup:", CHAR(10), "- Ide visual konten yang kreatif dan sangat detail, termasuk saran untuk setiap panel (jika carousel) atau *scene* (jika video), dan elemen visual penunjang untuk format yang dipilih.", CHAR(10), "- Script hook yang sangat kuat, memancing rasa penasaran, relevan dengan audiens, dan selaras dengan storytelling framework.", CHAR(10), "- Isi konten utama yang informatif, *engaging*, **memecahkan masalah audiens secara langsung, dan secara subtil menonjolkan keunikan saya sebagai '", 'CONTENT PILLAR MAPPING'!C5, "'.** Sesuaikan dengan gaya komunikasi saya, dengan fokus pada nilai tambah '", F18, "'.", CHAR(10), "- Call-to-Action (CTA) yang bervariatif, jelas, dan mendorong interaksi atau langkah selanjutnya (misalnya: follow, komen, share, save, kunjungi link di bio, daftar webinar, beli produk).", CHAR(10), "- Caption lengkap yang meliputi framework copywriting (Headline yang menarik, Bodycopy yang persuasif, dan CTA lagi di dalamnya), serta hashtag yang relevan dan trending.", CHAR(10), CHAR(10), "**Penting:** Untuk pilihan pertama dari script yang Anda hasilkan, mohon kembangkan menjadi **satu script yang paling detail dan komprehensif**, seolah-olah siap digunakan untuk produksi, dengan semua elemen visual dan naratif yang sangat jelas. Berikan 3"&"-5 pilihan script yang bervariasi, unik, dan siap pakai.", CHAR(10), "Pastikan outputnya:", CHAR(10), "✔ Kreatif, menarik, inovatif, dan punya potensi viral sesuai tren terkini.", CHAR(10), "✔ Sangat relevan dengan target audiens saya (", 'CONTENT PILLAR MAPPING'!D18, ", khusus ", 'CONTENT PILLAR MAPPING'!D19, ") dan membantu mereka menyelesaikan masalah atau mencapai tujuan mereka.", CHAR(10), "✔ Membantuku membangun personal branding yang kuat dan sustainable, sesuai dengan Positioning saya sebagai '", 'CONTENT PILLAR MAPPING'!C5, "' dan Brand Archetype '", 'CONTENT PILLAR MAPPING'!D10, "'.", CHAR(10), "✔ Kemas dalam bentuk tabel agar rapi, mudah di baca dan dipahami, dengan kolom 'Judul Konten', 'Pilar', 'Format', 'Draft Script', 'CTA', 'Saran Visual', dan 'Full Caption'. (Kosongkan kolom Link Prompt jika ada)." ), "") | L18: 4 | M18: Before & After: Menunjukkan transformasi dari kondisi lama ke kondisi baru yang lebih baik.
B19: Banyak Lomba, Sedikit Waktu: Gimana Cara Prioritasin yang Paling Potensial? | C19: Opportunity Content (Informasi) | D19: Carousel | E19: Instagram | F19: Solusi | G19: Problem-Solution | H19: =IF(H9<>"",HYPERLINK("https://chatgpt.com/?q="&ENCODEURL(H9),"👉 Klik untuk Generate Script! 🔥"),"") | I19: Template - Skrip Konten Carousels & Reels.docx | J19: Konten prioritas keputusan untuk anak muda yang punya banyak pilihan lomba tapi waktu dan energi terbatas. | K19: =IF(AND(B19<>"", C19<>"", D19<>"", E19<>"", F19<>"", G19<>"", J19<>"", 'CONTENT PILLAR MAPPING'!C2<>"", 'CONTENT PILLAR MAPPING'!E2<>"", 'CONTENT PILLAR MAPPING'!F2<>"", 'CONTENT PILLAR MAPPING'!C5<>"", 'CONTENT PILLAR MAPPING'!C10<>"", 'CONTENT PILLAR MAPPING'!D10<>"", 'CONTENT PILLAR MAPPING'!E10<>"", 'CONTENT PILLAR MAPPING'!D18<>"", 'CONTENT PILLAR MAPPING'!D19<>""), CONCATENATE( "Sebagai seorang top konten kreator dengan niche utama '", 'CONTENT PILLAR MAPPING'!C2, "', spesifik kategori '", 'CONTENT PILLAR MAPPING'!E2, "', dan super spesifik '", 'CONTENT PILLAR MAPPING'!F2, "', yang dikenal sebagai '", 'CONTENT PILLAR MAPPING'!C5, "'.", CHAR(10), "Saya memiliki Tone of Voice: '", 'CONTENT PILLAR MAPPING'!C10, "', Brand Archetype: '", 'CONTENT PILLAR MAPPING'!D10, "', dan Deskripsi Gaya Komunikasi: '", 'CONTENT PILLAR MAPPING'!E10, "'.", CHAR(10), "Target audiens saya adalah: '", 'CONTENT PILLAR MAPPING'!D18, "', dengan segmentasi audiens: '", 'CONTENT PILLAR MAPPING'!D19, "'.", CHAR(10), CHAR(10), "Mohon buatkan script konten yang **sangat powerful, menarik, inovatif, dan siap pakai** dengan judul ide '", B19, "'.", CHAR(10), "Konten ini memiliki pilar '", C19, "', nilai tambah utama '", F19, "', dan akan menggunakan storytelling framework '", G19, "'.", CHAR(10), "Gambaran singkat ide kontennya adalah: '", J19, "'.", CHAR(10), "Konten ini akan diunggah di platform '", E19, "' dengan format '", D19, "'.", CHAR(10), CHAR(10), "Script harus mencakup:", CHAR(10), "- Ide visual konten yang kreatif dan sangat detail, termasuk saran untuk setiap panel (jika carousel) atau *scene* (jika video), dan elemen visual penunjang untuk format yang dipilih.", CHAR(10), "- Script hook yang sangat kuat, memancing rasa penasaran, relevan dengan audiens, dan selaras dengan storytelling framework.", CHAR(10), "- Isi konten utama yang informatif, *engaging*, **memecahkan masalah audiens secara langsung, dan secara subtil menonjolkan keunikan saya sebagai '", 'CONTENT PILLAR MAPPING'!C5, "'.** Sesuaikan dengan gaya komunikasi saya, dengan fokus pada nilai tambah '", F19, "'.", CHAR(10), "- Call-to-Action (CTA) yang bervariatif, jelas, dan mendorong interaksi atau langkah selanjutnya (misalnya: follow, komen, share, save, kunjungi link di bio, daftar webinar, beli produk).", CHAR(10), "- Caption lengkap yang meliputi framework copywriting (Headline yang menarik, Bodycopy yang persuasif, dan CTA lagi di dalamnya), serta hashtag yang relevan dan trending.", CHAR(10), CHAR(10), "**Penting:** Untuk pilihan pertama dari script yang Anda hasilkan, mohon kembangkan menjadi **satu script yang paling detail dan komprehensif**, seolah-olah siap digunakan untuk produksi, dengan semua elemen visual dan naratif yang sangat jelas. Berikan 3"&"-5 pilihan script yang bervariasi, unik, dan siap pakai.", CHAR(10), "Pastikan outputnya:", CHAR(10), "✔ Kreatif, menarik, inovatif, dan punya potensi viral sesuai tren terkini.", CHAR(10), "✔ Sangat relevan dengan target audiens saya (", 'CONTENT PILLAR MAPPING'!D18, ", khusus ", 'CONTENT PILLAR MAPPING'!D19, ") dan membantu mereka menyelesaikan masalah atau mencapai tujuan mereka.", CHAR(10), "✔ Membantuku membangun personal branding yang kuat dan sustainable, sesuai dengan Positioning saya sebagai '", 'CONTENT PILLAR MAPPING'!C5, "' dan Brand Archetype '", 'CONTENT PILLAR MAPPING'!D10, "'.", CHAR(10), "✔ Kemas dalam bentuk tabel agar rapi, mudah di baca dan dipahami, dengan kolom 'Judul Konten', 'Pilar', 'Format', 'Draft Script', 'CTA', 'Saran Visual', dan 'Full Caption'. (Kosongkan kolom Link Prompt jika ada)." ), "") | L19: 5 | M19: Case Study/Testimonial: Kisah nyata keberhasilan atau pengalaman positif.
B20: Setelah Ikut Lomba, Jangan Cuma Nunggu Menang, Lakuin 4 Hal Ini | C20: Opportunity Content (Informasi) | D20: Carousel | E20: Instagram | F20: Perspektif Baru | G20: Before-After | H20: =IF(H9<>"",HYPERLINK("https://chatgpt.com/?q="&ENCODEURL(H9),"👉 Klik untuk Generate Script! 🔥"),"") | I20: Template - Skrip Konten Carousels & Reels.docx | J20: Konten perspektif baru bahwa value ikut lomba tidak berhenti di menang atau kalah, tapi bisa diolah jadi aset growth. | K20: =IF(AND(B20<>"", C20<>"", D20<>"", E20<>"", F20<>"", G20<>"", J20<>"", 'CONTENT PILLAR MAPPING'!C2<>"", 'CONTENT PILLAR MAPPING'!E2<>"", 'CONTENT PILLAR MAPPING'!F2<>"", 'CONTENT PILLAR MAPPING'!C5<>"", 'CONTENT PILLAR MAPPING'!C10<>"", 'CONTENT PILLAR MAPPING'!D10<>"", 'CONTENT PILLAR MAPPING'!E10<>"", 'CONTENT PILLAR MAPPING'!D18<>"", 'CONTENT PILLAR MAPPING'!D19<>""), CONCATENATE( "Sebagai seorang top konten kreator dengan niche utama '", 'CONTENT PILLAR MAPPING'!C2, "', spesifik kategori '", 'CONTENT PILLAR MAPPING'!E2, "', dan super spesifik '", 'CONTENT PILLAR MAPPING'!F2, "', yang dikenal sebagai '", 'CONTENT PILLAR MAPPING'!C5, "'.", CHAR(10), "Saya memiliki Tone of Voice: '", 'CONTENT PILLAR MAPPING'!C10, "', Brand Archetype: '", 'CONTENT PILLAR MAPPING'!D10, "', dan Deskripsi Gaya Komunikasi: '", 'CONTENT PILLAR MAPPING'!E10, "'.", CHAR(10), "Target audiens saya adalah: '", 'CONTENT PILLAR MAPPING'!D18, "', dengan segmentasi audiens: '", 'CONTENT PILLAR MAPPING'!D19, "'.", CHAR(10), CHAR(10), "Mohon buatkan script konten yang **sangat powerful, menarik, inovatif, dan siap pakai** dengan judul ide '", B20, "'.", CHAR(10), "Konten ini memiliki pilar '", C20, "', nilai tambah utama '", F20, "', dan akan menggunakan storytelling framework '", G20, "'.", CHAR(10), "Gambaran singkat ide kontennya adalah: '", J20, "'.", CHAR(10), "Konten ini akan diunggah di platform '", E20, "' dengan format '", D20, "'.", CHAR(10), CHAR(10), "Script harus mencakup:", CHAR(10), "- Ide visual konten yang kreatif dan sangat detail, termasuk saran untuk setiap panel (jika carousel) atau *scene* (jika video), dan elemen visual penunjang untuk format yang dipilih.", CHAR(10), "- Script hook yang sangat kuat, memancing rasa penasaran, relevan dengan audiens, dan selaras dengan storytelling framework.", CHAR(10), "- Isi konten utama yang informatif, *engaging*, **memecahkan masalah audiens secara langsung, dan secara subtil menonjolkan keunikan saya sebagai '", 'CONTENT PILLAR MAPPING'!C5, "'.** Sesuaikan dengan gaya komunikasi saya, dengan fokus pada nilai tambah '", F20, "'.", CHAR(10), "- Call-to-Action (CTA) yang bervariatif, jelas, dan mendorong interaksi atau langkah selanjutnya (misalnya: follow, komen, share, save, kunjungi link di bio, daftar webinar, beli produk).", CHAR(10), "- Caption lengkap yang meliputi framework copywriting (Headline yang menarik, Bodycopy yang persuasif, dan CTA lagi di dalamnya), serta hashtag yang relevan dan trending.", CHAR(10), CHAR(10), "**Penting:** Untuk pilihan pertama dari script yang Anda hasilkan, mohon kembangkan menjadi **satu script yang paling detail dan komprehensif**, seolah-olah siap digunakan untuk produksi, dengan semua elemen visual dan naratif yang sangat jelas. Berikan 3"&"-5 pilihan script yang bervariasi, unik, dan siap pakai.", CHAR(10), "Pastikan outputnya:", CHAR(10), "✔ Kreatif, menarik, inovatif, dan punya potensi viral sesuai tren terkini.", CHAR(10), "✔ Sangat relevan dengan target audiens saya (", 'CONTENT PILLAR MAPPING'!D18, ", khusus ", 'CONTENT PILLAR MAPPING'!D19, ") dan membantu mereka menyelesaikan masalah atau mencapai tujuan mereka.", CHAR(10), "✔ Membantuku membangun personal branding yang kuat dan sustainable, sesuai dengan Positioning saya sebagai '", 'CONTENT PILLAR MAPPING'!C5, "' dan Brand Archetype '", 'CONTENT PILLAR MAPPING'!D10, "'.", CHAR(10), "✔ Kemas dalam bentuk tabel agar rapi, mudah di baca dan dipahami, dengan kolom 'Judul Konten', 'Pilar', 'Format', 'Draft Script', 'CTA', 'Saran Visual', dan 'Full Caption'. (Kosongkan kolom Link Prompt jika ada)." ), "") | L20: 6 | M20: The 'Why' Story: Menjelaskan alasan di balik nilai atau misi Anda.
B21: Lomba Online vs Offline, Mana yang Lebih Strategis Buat Pelajar dan Mahasiswa? | C21: Opportunity Content (Informasi) | D21: Carousel | E21: Instagram | F21: Edukasi/Wawasan | G21: The Why Story | H21: =IF(H9<>"",HYPERLINK("https://chatgpt.com/?q="&ENCODEURL(H9),"👉 Klik untuk Generate Script! 🔥"),"") | I21: Template - Skrip Konten Carousels & Reels.docx | J21: Konten perbandingan yang bantu audiens memilih format lomba paling strategis sesuai tujuan dan kondisi mereka. | K21: =IF(AND(B21<>"", C21<>"", D21<>"", E21<>"", F21<>"", G21<>"", J21<>"", 'CONTENT PILLAR MAPPING'!C2<>"", 'CONTENT PILLAR MAPPING'!E2<>"", 'CONTENT PILLAR MAPPING'!F2<>"", 'CONTENT PILLAR MAPPING'!C5<>"", 'CONTENT PILLAR MAPPING'!C10<>"", 'CONTENT PILLAR MAPPING'!D10<>"", 'CONTENT PILLAR MAPPING'!E10<>"", 'CONTENT PILLAR MAPPING'!D18<>"", 'CONTENT PILLAR MAPPING'!D19<>""), CONCATENATE( "Sebagai seorang top konten kreator dengan niche utama '", 'CONTENT PILLAR MAPPING'!C2, "', spesifik kategori '", 'CONTENT PILLAR MAPPING'!E2, "', dan super spesifik '", 'CONTENT PILLAR MAPPING'!F2, "', yang dikenal sebagai '", 'CONTENT PILLAR MAPPING'!C5, "'.", CHAR(10), "Saya memiliki Tone of Voice: '", 'CONTENT PILLAR MAPPING'!C10, "', Brand Archetype: '", 'CONTENT PILLAR MAPPING'!D10, "', dan Deskripsi Gaya Komunikasi: '", 'CONTENT PILLAR MAPPING'!E10, "'.", CHAR(10), "Target audiens saya adalah: '", 'CONTENT PILLAR MAPPING'!D18, "', dengan segmentasi audiens: '", 'CONTENT PILLAR MAPPING'!D19, "'.", CHAR(10), CHAR(10), "Mohon buatkan script konten yang **sangat powerful, menarik, inovatif, dan siap pakai** dengan judul ide '", B21, "'.", CHAR(10), "Konten ini memiliki pilar '", C21, "', nilai tambah utama '", F21, "', dan akan menggunakan storytelling framework '", G21, "'.", CHAR(10), "Gambaran singkat ide kontennya adalah: '", J21, "'.", CHAR(10), "Konten ini akan diunggah di platform '", E21, "' dengan format '", D21, "'.", CHAR(10), CHAR(10), "Script harus mencakup:", CHAR(10), "- Ide visual konten yang kreatif dan sangat detail, termasuk saran untuk setiap panel (jika carousel) atau *scene* (jika video), dan elemen visual penunjang untuk format yang dipilih.", CHAR(10), "- Script hook yang sangat kuat, memancing rasa penasaran, relevan dengan audiens, dan selaras dengan storytelling framework.", CHAR(10), "- Isi konten utama yang informatif, *engaging*, **memecahkan masalah audiens secara langsung, dan secara subtil menonjolkan keunikan saya sebagai '", 'CONTENT PILLAR MAPPING'!C5, "'.** Sesuaikan dengan gaya komunikasi saya, dengan fokus pada nilai tambah '", F21, "'.", CHAR(10), "- Call-to-Action (CTA) yang bervariatif, jelas, dan mendorong interaksi atau langkah selanjutnya (misalnya: follow, komen, share, save, kunjungi link di bio, daftar webinar, beli produk).", CHAR(10), "- Caption lengkap yang meliputi framework copywriting (Headline yang menarik, Bodycopy yang persuasif, dan CTA lagi di dalamnya), serta hashtag yang relevan dan trending.", CHAR(10), CHAR(10), "**Penting:** Untuk pilihan pertama dari script yang Anda hasilkan, mohon kembangkan menjadi **satu script yang paling detail dan komprehensif**, seolah-olah siap digunakan untuk produksi, dengan semua elemen visual dan naratif yang sangat jelas. Berikan 3"&"-5 pilihan script yang bervariasi, unik, dan siap pakai.", CHAR(10), "Pastikan outputnya:", CHAR(10), "✔ Kreatif, menarik, inovatif, dan punya potensi viral sesuai tren terkini.", CHAR(10), "✔ Sangat relevan dengan target audiens saya (", 'CONTENT PILLAR MAPPING'!D18, ", khusus ", 'CONTENT PILLAR MAPPING'!D19, ") dan membantu mereka menyelesaikan masalah atau mencapai tujuan mereka.", CHAR(10), "✔ Membantuku membangun personal branding yang kuat dan sustainable, sesuai dengan Positioning saya sebagai '", 'CONTENT PILLAR MAPPING'!C5, "' dan Brand Archetype '", 'CONTENT PILLAR MAPPING'!D10, "'.", CHAR(10), "✔ Kemas dalam bentuk tabel agar rapi, mudah di baca dan dipahami, dengan kolom 'Judul Konten', 'Pilar', 'Format', 'Draft Script', 'CTA', 'Saran Visual', dan 'Full Caption'. (Kosongkan kolom Link Prompt jika ada)." ), "") | L21: 7 | M21: In Media Res: Memulai cerita di tengah aksi, lalu kilas balik menjelaskan latar belakang.
